<?xml version="1.0"?>
<!-- This URDF was automatically created by SolidWorks to URDF Exporter! Originally created by Stephen Brawner (brawner@gmail.com) 
     Commit Version: 1.6.0-4-g7f85cfe  Build Version: 1.6.7995.38578
     For more information, please see http://wiki.ros.org/sw_urdf_exporter -->
<robot name="sim" xmlns:xacro="http://www.ros.org/wiki/xacro">
<xacro:macro name="chassis">

    <!-- base_link -->
    <link name="base_link">
        <inertial>
            <origin xyz="0.09975 -4.0621E-17 0.11305" rpy="0 0 0" />
            <mass value="0.023381" />
            <inertia ixx="4.0829E-06" ixy="-5.2777E-22" ixz="-4.9533E-22"
                     iyy="2.8092E-06" iyz="1.835E-23"   izz="2.0585E-06" />
        </inertial>
        <visual>
            <origin xyz="0.00 0.0 0.11" rpy="0 0 0" />
            <geometry>
                <box size="0.412 0.359 0.163" />
            </geometry>
            <material name="">
                <color rgba="0.89804 0.91765 0.92941 1" />
            </material>
        </visual>
        <collision>
            <origin xyz="0.00 0.0 0.11" rpy="0 0 0" />
            <geometry>
                <box size="0.412 0.359 0.163" />
            </geometry>
        </collision>
    </link>
    <gazebo reference="base_link">
        <material>Gazebo/White</material>
    </gazebo>

    <!-- right front wheel -->
    <link name="RightFrontWheel_Link">
        <inertial>
            <origin xyz="0 0 0" rpy="0 0 0" />
            <mass value="0.38714" />
            <inertia ixx="0.0" ixy="0.0" ixz="0.0"
                     iyy="0.0" iyz="0.0" izz="0.0" />
        </inertial>
        <visual>
            <origin xyz="0 0 0" rpy="1.57079637 0 0" />
            <geometry>
                <cylinder length="0.001" radius="0.07"/>
            </geometry>
            <material name="">
                <color rgba="0.5 0.5 0.5 1" />
            </material>
        </visual>
        <collision>
            <origin xyz="0 0 0" rpy="1.57079637 0 0" />
            <geometry>
                <cylinder length="0.001" radius="0.07"/>
            </geometry>
        </collision>
    </link>
    <gazebo reference="RightFrontWheel_Link">
        <material>Gazebo/DarkGrey</material>
        <mu1>0.00001</mu1>
        <mu2>0.00001</mu2>
    </gazebo>
    <joint name="RightFrontWheel_joint" type="continuous">
        <origin xyz="0.13025 -0.15995 0.07" rpy="0 0 0" />
        <parent link="base_link" />
        <child link="RightFrontWheel_Link" />
        <axis xyz="0 1 0" />
    </joint>

    <!-- right back wheel -->
    <link name="RightBackWheel_Link">
        <inertial>
            <origin xyz="0 0 0" rpy="0 0 0" />
            <mass value="0.38714" />
            <inertia ixx="0.0" ixy="0.0" ixz="0.0"
                     iyy="0.0" iyz="0.0" izz="0.0" />
        </inertial>
        <visual>
            <origin xyz="0 0 0" rpy="1.57079637 0 0" />
            <geometry>
                <cylinder length="0.001" radius="0.07"/>
            </geometry>
            <material name="">
                <color rgba="0.5 0.5 0.5 1" />
            </material>
        </visual>
        <collision>
            <origin xyz="0 0 0" rpy="1.57079637 0 0" />
            <geometry>
                <cylinder length="0.001" radius="0.07"/>
            </geometry>
        </collision>
    </link>
    <gazebo reference="RightBackWheel_Link">
        <material>Gazebo/DarkGrey</material>
        <mu1>0.00001</mu1>
        <mu2>0.00001</mu2>
    </gazebo>
    <joint name="RightBackWheel_joint" type="continuous">
        <origin xyz="-0.13025 -0.15995 0.07" rpy="0 0 0" />
        <parent link="base_link" />
        <child link="RightBackWheel_Link" />
        <axis xyz="0 1 0" />
    </joint>

    <!-- left front wheel -->
    <link name="LeftFrontWheel_Link">
        <inertial>
            <origin xyz="0 0 0" rpy="0 0 0" />
            <mass value="0.38714" />
            <inertia ixx="0.0" ixy="0.0" ixz="0.0"
                     iyy="0.0" iyz="0.0" izz="0.0" />
        </inertial>
        <visual>
            <origin xyz="0 0 0" rpy="1.57079637 0 0" />
            <geometry>
                <cylinder length="0.001" radius="0.07"/>
            </geometry>
            <material name="">
                <color rgba="0.5 0.5 0.5 1" />
            </material>
        </visual>
        <collision>
            <origin xyz="0 0 0" rpy="1.57079637 0 0" />
            <geometry>
                <cylinder length="0.001" radius="0.07"/>
            </geometry>
        </collision>
    </link>
    <gazebo reference="LeftFrontWheel_Link">
        <material>Gazebo/DarkGrey</material>
        <mu1>0.00001</mu1>
        <mu2>0.00001</mu2>
    </gazebo>
    <joint name="LeftFrontWheel_joint" type="continuous">
        <origin xyz="0.13025 0.15995 0.07" rpy="0 0 0" />
        <parent link="base_link" />
        <child link="LeftFrontWheel_Link" />
        <axis xyz="0 -1 0" />
    </joint>

    <!-- left back wheel -->
    <link name="LeftBackWheel_Link">
        <inertial>
            <origin xyz="0 0 0" rpy="0 0 0" />
            <mass value="0.38714" />
            <inertia ixx="0.0" ixy="0.0" ixz="0.0"
                     iyy="0.0" iyz="0.0" izz="0.0" />
        </inertial>
        <visual>
            <origin xyz="0 0 0" rpy="1.57079637 0 0" />
            <geometry>
                <cylinder length="0.001" radius="0.07"/>
            </geometry>
            <material name="">
                <color rgba="0.5 0.5 0.5 1" />
            </material>
        </visual>
        <collision>
            <origin xyz="0 0 0" rpy="1.57079637 0 0" />
            <geometry>
                <cylinder length="0.001" radius="0.07"/>
            </geometry>
        </collision>
    </link>
    <gazebo reference="LeftBackWheel_Link">
        <material>Gazebo/DarkGrey</material>
        <mu1>0.00001</mu1>
        <mu2>0.00001</mu2>
    </gazebo>
    <joint name="LeftBackWheel_joint" type="continuous">
        <origin xyz="-0.13025 0.15995 0.07" rpy="0 0 0" />
        <parent link="base_link" />
        <child link="LeftBackWheel_Link" />
        <axis xyz="0 -1 0" />
    </joint>

    <!-- controller -->
    <gazebo>
        <plugin name="mecanum_controller" filename="libgazebo_ros_planar_move.so">
            <commandTopic>cmd_vel</commandTopic>
            <odometryTopic>odom</odometryTopic>
            <odometryFrame>odom</odometryFrame>
            <rightFrontJoint>RightFrontWheel_joint</rightFrontJoint>
            <rightRearJoint>RightBackWheel_joint</rightRearJoint>
            <leftFrontJoint>LeftFrontWheel_joint</leftFrontJoint>
            <leftRearJoint>LeftBackWheel_joint</leftRearJoint>
            <odometryRate>100</odometryRate>
            <robotBaseFrame>base_link</robotBaseFrame>
            <broadcastTF>1</broadcastTF>
        </plugin>
    </gazebo>

</xacro:macro>
</robot>
